<?xml version="1.0" ?>
<mujoco>
    <asset>
        <texture builtin="gradient" height="100" rgb1="1 1 1" rgb2="0 0 0" type="skybox" width="100"/>
        <texture builtin="flat" height="1278" mark="cross" markrgb="1 1 1" name="texgeom" random="0.01" rgb1="0.8 0.6 0.4" rgb2="0.8 0.6 0.4" type="cube" width="127"/>
        <texture builtin="checker" height="100" name="texplane" rgb1="0 0 0" rgb2="0.8 0.8 0.8" type="2d" width="100"/>
        <material name="MatPlane" reflectance="0.5" shininess="1" specular="1" texrepeat="60 60" texture="texplane"/>
        <material name="geom" texture="texgeom" texuniform="true"/>
        <mesh file="joint_socket.stl" name= "joint_socket" scale="0.001 0.001 0.001"></mesh>

    </asset>
    <option timestep="0.0001" />

    <worldbody>
        <light cutoff="100" diffuse="1 1 1" dir="-0 0 -1.3" directional="true" exponent="1" pos="0 0 1.3" specular=".1 .1 .1"/>
        <geom conaffinity="1" condim="3" material="MatPlane" name="floor" pos="0 0 0" rgba="0.8 0.9 0.8 1" size="5 5 0.1" type="plane"/>
        <body pos="0 0 1">
            <joint type="free"/>
            <geom type="box" pos="0 0 0.05" size="0.125 0.025 0.001"/>


            <!-- <body name="joint_fc_1">
                <geom type="box" pos="0 -0.015 0.06" size="0.01 0.01 0.01"/>
            </body>
            <body name="joint_fr_1">
                       <geom type="capsule" size="0.0105" fromto="-0.061 -0.01 0.08 -0.061 -0.025 0.08" />
         <geom type="box" pos="0.1 -0.015 0.04" size="0.01 0.01 0.01"/>
            </body>
            <body name="joint_fl_1">
                <geom type="box" pos="-0.1 -0.015 0.04" size="0.01 0.01 0.01"/>
            </body> -->
            <site name="contact_sensor" type="box" pos="0 -0.015 0.06" size="0.025 0.011 0.011" rgba="1 1 0 0.5"/>
            <body name="plug">
                <geom type="capsule" size="0.0105" fromto="0.061 -0.01 0.08 0.061 -0.045 0.08" />
                <body name="left_plug">
                    <joint name="plug_left" type="hinge" axis="0 0 1" pos="0.061 -0.045 0.08" limited="true" range="0 90" />
                    <geom type="capsule" size="0.0105" fromto="0.061 -0.0651 0.08 0.061 -0.07 0.08" />
                </body>
                <geom type="capsule" size="0.0105" fromto="-0.061 -0.01 0.08 -0.061 -0.045 0.08" />
                <body name="right_plug">
                    <joint name="plug_right" type="hinge" axis="0 0 1" pos="-0.061 -0.045 0.08" limited="true" range="-90 0" />
                    <geom type="capsule" size="0.0105" fromto="-0.061 -0.0651 0.08 -0.061 -0.07 0.08" />
                </body>
            </body>


            <body pos="0.06 -0.02 0 ">
                <joint name="support_fr_1" type="hinge" axis="1 0 0" pos="0 0 0.04" limited="true" range="-90 0"/>
                <geom type="capsule" size="0.005" fromto="0 0 0.04 0 0 -0.035" />
                <body>
                    <joint pos="0 0 -0.045" type="ball"/>
                    <geom type="sphere" size="0.005" pos="0 0 -0.045"/>
                </body>
            </body>
            <body pos="-0.06 -0.02 0 ">
                <joint name="support_fl_1" type="hinge" axis="1 0 0" pos="0 0 0.04" limited="true" range="-90 0"/>
                <geom type="capsule" size="0.005" fromto="0 0 0.04 0 0 -0.035" />
                <body>
                    <joint pos="0 0 -0.045" type="ball"/>
                    <geom type="sphere" size="0.005" pos="0 0 -0.045"/>
                </body>
            </body>


            <geom type="box" pos="0 0.05 0.05" size="0.04 0.025 0.001"/>
            <geom type="box" pos="0 0.075 0.0175" size="0.04 0.001 0.015"/>
            <body>
                <joint type="hinge" pos="0 0.075 0" axis="1 0 0" springdamper="1.5 0.01" limited="true" range="-90 90" />
                <geom type="box" pos="0.083 0.075 0.0175" size="0.04 0.001 0.015"/>
                <geom type="box" pos="-0.083 0.075 0.0175" size="0.04 0.001 0.015"/>
                <geom type="box" pos="0.083 0.1 0.05" size="0.04 0.025 0.001"/>
                <geom type="box" pos="-0.083 0.1 0.05" size="0.04 0.025 0.001"/>
                <geom type="box" pos="0 0.175 0.05" size="0.125 0.05 0.001"/>

                <body name="socket">
                    <geom type="mesh" mesh="joint_socket" pos="0 0.22 0.08"></geom>
                </body>
                <!-- <body name="joint_bc_1">
                    <geom type="box" pos="0 0.215 0.06" size="0.01 0.01 0.01"/>
                </body>
                <body name="joint_br_1">
                    <geom type="box" pos="0.1 0.215 0.04" size="0.01 0.01 0.01"/>
                </body>
                <body name="joint_bl_1">
                    <geom type="box" pos="-0.1 0.215 0.04" size="0.01 0.01 0.01"/>
                </body> -->



                <body pos="0 0.22 0 ">
                    <joint name="support_b_1" type="hinge" axis="1 0 0" pos="0 0 0.04" limited="true" range="-90 0"/>
                    <geom type="capsule" size="0.005" fromto="0 0 0.04 0 0 -0.035" />
                    <body>
                        <joint pos="0 0 -0.045" type="ball"/>
                        <geom type="sphere" size="0.005" pos="0 0 -0.045"/>
                    </body>
                </body>
            </body>
            <body>
                <joint name="RW1" type="hinge" axis="1 0 0" pos="-0.14 0.075 0"/>
                <geom type="ellipsoid" size="0.01 0.05 0.05" rgba="0 0 1 1" pos="0.14 0.075 0"/>
            </body>
            <body>
                <joint name ="LW1" type="hinge" axis="1 0 0" pos="0.14 0.075 0"/>
                <geom type="ellipsoid" size="0.01 0.05 0.05" rgba="0 0 1 1" pos="-0.14 0.075 0"/>
            </body>
        </body>
    </worldbody>
    <actuator>
        <motor joint="LW1"/>
        <motor joint="RW1"/>
        <!-- <velocity joint="LW1"/>
        <velocity joint="RW1"/> -->
        <motor joint="support_fr_1"/>
        <motor joint="support_fl_1"/>
        <motor joint="support_b_1"/>
        <motor joint="plug_left"/>
        <motor joint="plug_right"/>
    </actuator>
    <sensor>
        <touch site="contact_sensor"/>
    </sensor>
</mujoco>